Workbook

Sheet 10.1
A1: 2020 - 2016 ,udwdwA egcnirevurutwf iawaejcaWr cnutogegukwtumuawq : 10.1 ulwvWt
A2: Table 10.1 : FLOW OF TOURISTS BY NATIONALITY, 2016 - 2020
A4: Country of Nationality | F4: udwdwA egcnirevurutwf | P4: cniawtcaws ctogWviawfiheb | Z4: އިތުރުވި މިންވަރު | AE4: Wviawfevirevcnwzwv
F5: No. of Tourists | P5: Percentage Share | Z5: % change over previous year | AE5: cawtumuawq
B6: 2012 | C6: 2013 | D6: 2014 | E6: 2015 | F6: 2016 | G6: 2017 | H6: 2018 | I6: 2019 | J6: 2020 | L6: 2012 | M6: 2013 | N6: 2014 | O6: 2015 | P6: 2016 | Q6: 2017 | R6: 2018 | S6: 2019 | T6: 2020 | V6: 2012 | W6: 2013 | X6: 2014 | Y6: 2015 | Z6: 2016 | AA6: 2017 | AB6: 2018 | AC6: 2019 | AD6: 2020
A7: Total | B7: =B8+B35+B50+B53+B58+B62 -> 958025 | C7: =C8+C35+C50+C53+C58+C62+C68+C69 -> 1125202 | D7: =D8+D35+D50+D53+D58+D62+D68+D69 -> 1204857 | E7: =E8+E35+E50+E53+E58+E62+E68+E69 -> 1234248 | F7: =F8+F35+F50+F53+F58+F62+F68+F69 -> 1286135 | G7: =G8+G35+G50+G53+G58+G62+G68+G69 -> 1389542 | H7: =H8+H35+H50+H53+H58+H62+H68+H69 -> 1484274 | I7: =I8+I35+I50+I53+I58+I62+I68+I69 -> 1702887 | J7: =J8+J35+J50+J53+J58+J62+J68+J69 -> 555494 | L7: =B7/B$7*100 -> 100 | M7: =C7/C$7*100 -> 100 | N7: =D7/D$7*100 -> 100 | O7: =E7/E$7*100 -> 100 | P7: =F7/F$7*100 -> 100 | Q7: =G7/G$7*100 -> 100 | R7: =H7/H$7*100 -> 100 | S7: =I7/I$7*100 -> 100 | T7: =J7/J$7*100 -> 100 | V7: 2.8659996 | W7: =(C7-B7)/B7*100 -> 17.450171 | X7: =(D7-C7)/C7*100 -> 7.0791733 | Y7: =(E7-D7)/D7*100 -> 2.4393766 | Z7: =(F7-E7)/E7*100 -> 4.2039363 | AA7: =(G7-F7)/F7*100 -> 8.0401358 | AB7: =(H7-G7)/G7*100 -> 6.8174981 | AC7: =(I7-H7)/H7*100 -> 14.728615 | AD7: =(J7-I7)/I7*100 -> -67.37928 | AE7: ޖުމްލަ
A8: Europe | B8: =SUM(B9:B34) -> 517807 | C8: =SUM(C9:C34) -> 527274 | D8: =SUM(D9:D34) -> 529291 | E8: =SUM(E9:E34) -> 535962 | F8: =SUM(F9:F34) -> 575176 | G8: =SUM(G9:G34) -> 646343 | H8: =SUM(H9:H34) -> 726420 | I8: =SUM(I9:I34) -> 833939 | J8: =SUM(J9:J34) -> 348349 | L8: =B8/B$7*100 -> 54.049425 | M8: =C8/C$7*100 -> 46.860386 | N8: =D8/D$7*100 -> 43.929778 | O8: =E8/E$7*100 -> 43.424174 | P8: =F8/F$7*100 -> 44.721277 | Q8: =G8/G$7*100 -> 46.514823 | R8: =H8/H$7*100 -> 48.941098 | S8: =I8/I$7*100 -> 48.972069 | T8: =J8/J$7*100 -> 62.709768 | V8: -3.7098541 | W8: =(C8-B8)/B8*100 -> 1.8282874 | X8: =(D8-C8)/C8*100 -> 0.38253356 | Y8: =(E8-D8)/D8*100 -> 1.2603653 | Z8: =(F8-E8)/E8*100 -> 7.3165635 | AA8: =(G8-F8)/F8*100 -> 12.373082 | AB8: =(H8-G8)/G8*100 -> 12.389242 | AC8: =(I8-H8)/H8*100 -> 14.801217 | AD8: =(J8-I8)/I8*100 -> -58.22848 | AE8: ޔޫރަޕް
A9: Austria | B9: 18164 | C9: 18140 | D9: 18726 | E9: 18981 | F9: 17654 | G9: 19709 | H9: 20391 | I9: 21839 | J9: 8103 | L9: =B9/B$7*100 -> 1.8959839 | M9: =C9/C$7*100 -> 1.612155 | N9: =D9/D$7*100 -> 1.5542093 | O9: =E9/E$7*100 -> 1.5378595 | P9: =F9/F$7*100 -> 1.3726397 | Q9: =G9/G$7*100 -> 1.418381 | R9: =H9/H$7*100 -> 1.373803 | S9: =I9/I$7*100 -> 1.2824691 | T9: =J9/J$7*100 -> 1.4587016 | V9: 9.0603422 | W9: =(C9-B9)/B9*100 -> -0.13212949 | X9: =(D9-C9)/C9*100 -> 3.23043 | Y9: =(E9-D9)/D9*100 -> 1.361743 | Z9: =(F9-E9)/E9*100 -> -6.9912017 | AA9: =(G9-F9)/F9*100 -> 11.640421 | AB9: =(H9-G9)/G9*100 -> 3.4603481 | AC9: =(I9-H9)/H9*100 -> 7.1011721 | AD9: =(J9-I9)/I9*100 -> -62.896653 | AE9: އޮސްޓްރިއާ | BA9: 2016 | BB9: 2017 | BC9: 2018 | BD9: 2019 | BE9: 2020
A10: Belgium | B10: 1509 | C10: 5130 | D10: 5195 | E10: 5250 | F10: 5571 | G10: 5854 | H10: 6492 | I10: 7305 | J10: 2921 | L10: =B10/B$7*100 -> 0.15751155 | M10: =C10/C$7*100 -> 0.45591814 | N10: =D10/D$7*100 -> 0.4311715 | O10: =E10/E$7*100 -> 0.42536022 | P10: =F10/F$7*100 -> 0.43315826 | Q10: =G10/G$7*100 -> 0.42128989 | R10: =H10/H$7*100 -> 0.43738555 | S10: =I10/I$7*100 -> 0.42897738 | T10: =J10/J$7*100 -> 0.52583826 | V10: -73.701638 | W10: =(C10-B10)/B10*100 -> 239.96024 | X10: =(D10-C10)/C10*100 -> 1.2670565 | Y10: =(E10-D10)/D10*100 -> 1.0587103 | Z10: =(F10-E10)/E10*100 -> 6.1142857 | AA10: =(G10-F10)/F10*100 -> 5.0798779 | AB10: =(H10-G10)/G10*100 -> 10.898531 | AC10: =(I10-H10)/H10*100 -> 12.523105 | AD10: =(J10-I10)/I10*100 -> -60.013689 | AE10: ބެލްޖިއަމް | AY10: 1 | AZ10: India | BA10: 66955 | BB10: 83019 | BC10: 90474 | BD10: 166030 | BE10: 62960
A11: Czech Republic | B11: 5588 | C11: 6421 | D11: 6450 | E11: 8105 | F11: 10338 | G11: 11459 | H11: 13229 | I11: 13423 | J11: 7282 | L11: =B11/B$7*100 -> 0.58328332 | M11: =C11/C$7*100 -> 0.57065309 | N11: =D11/D$7*100 -> 0.53533324 | O11: =E11/E$7*100 -> 0.65667516 | P11: =F11/F$7*100 -> 0.80380364 | Q11: =G11/G$7*100 -> 0.82466021 | R11: =H11/H$7*100 -> 0.89127749 | S11: =I11/I$7*100 -> 0.7882496 | T11: =J11/J$7*100 -> 1.3109052 | V11: -13.645495 | W11: =(C11-B11)/B11*100 -> 14.906943 | X11: =(D11-C11)/C11*100 -> 0.45164305 | Y11: =(E11-D11)/D11*100 -> 25.658915 | Z11: =(F11-E11)/E11*100 -> 27.550895 | AA11: =(G11-F11)/F11*100 -> 10.84349 | AB11: =(H11-G11)/G11*100 -> 15.446374 | AC11: =(I11-H11)/H11*100 -> 1.4664752 | AD11: =(J11-I11)/I11*100 -> -45.749832 | AE11: ޗެކްރިޕަބްލިކް | AY11: 2 | AZ11: Russia | BA11: 46522 | BB11: 61931 | BC11: 70935 | BD11: 83369 | BE11: 61387
A12: Denmark | B12: 3493 | C12: 4055 | D12: 5008 | E12: 8418 | F12: 9747 | G12: 10629 | H12: 11133 | I12: 10621 | J12: 3938 | L12: =B12/B$7*100 -> 0.36460426 | M12: =C12/C$7*100 -> 0.36037974 | N12: =D12/D$7*100 -> 0.41565099 | O12: =E12/E$7*100 -> 0.68203473 | P12: =F12/F$7*100 -> 0.75785201 | Q12: =G12/G$7*100 -> 0.7649283 | R12: =H12/H$7*100 -> 0.75006367 | S12: =I12/I$7*100 -> 0.62370551 | T12: =J12/J$7*100 -> 0.70891855 | V12: 10.085093 | W12: =(C12-B12)/B12*100 -> 16.089322 | X12: =(D12-C12)/C12*100 -> 23.50185 | Y12: =(E12-D12)/D12*100 -> 68.091054 | Z12: =(F12-E12)/E12*100 -> 15.787598 | AA12: =(G12-F12)/F12*100 -> 9.0489381 | AB12: =(H12-G12)/G12*100 -> 4.7417443 | AC12: =(I12-H12)/H12*100 -> -4.5989401 | AD12: =(J12-I12)/I12*100 -> -62.922512 | AE12: ޑެންމާރކް | AY12: 3 | AZ12: United Kingdom | BA12: 101843 | BB12: 103977 | BC12: 114602 | BD12: 126199 | BE12: 52720
A13: Finland | B13: 1402 | C13: 1549 | D13: 5627 | E13: 2109 | F13: 2589 | G13: 3705 | H13: 5682 | I13: 5315 | J13: 2128 | L13: =B13/B$7*100 -> 0.14634274 | M13: =C13/C$7*100 -> 0.13766417 | N13: =D13/D$7*100 -> 0.46702638 | O13: =E13/E$7*100 -> 0.17087328 | P13: =F13/F$7*100 -> 0.2013008 | Q13: =G13/G$7*100 -> 0.26663462 | R13: =H13/H$7*100 -> 0.38281342 | S13: =I13/I$7*100 -> 0.31211701 | T13: =J13/J$7*100 -> 0.38308245 | V13: -8.6644951 | W13: =(C13-B13)/B13*100 -> 10.485021 | X13: =(D13-C13)/C13*100 -> 263.26662 | Y13: =(E13-D13)/D13*100 -> -62.519993 | Z13: =(F13-E13)/E13*100 -> 22.759602 | AA13: =(G13-F13)/F13*100 -> 43.105446 | AB13: =(H13-G13)/G13*100 -> 53.360324 | AC13: =(I13-H13)/H13*100 -> -6.4589933 | AD13: =(J13-I13)/I13*100 -> -59.962371 | AE13: ފިންލޭންޑް | AY13: 4 | AZ13: Italy | BA13: 71202 | BB13: 88848 | BC13: 105297 | BD13: 136343 | BE13: 46690
A14: France | B14: 56775 | C14: 54328 | D14: 50656 | E14: 42024 | F14: 40487 | G14: 42365 | H14: 50476 | I14: 59738 | J14: 28031 | L14: =B14/B$7*100 -> 5.9262545 | M14: =C14/C$7*100 -> 4.8282886 | N14: =D14/D$7*100 -> 4.2043164 | O14: =E14/E$7*100 -> 3.4048263 | P14: =F14/F$7*100 -> 3.1479588 | Q14: =G14/G$7*100 -> 3.0488463 | R14: =H14/H$7*100 -> 3.4007198 | S14: =I14/I$7*100 -> 3.5080425 | T14: =J14/J$7*100 -> 5.0461391 | V14: -4.8899387 | W14: =(C14-B14)/B14*100 -> -4.3099956 | X14: =(D14-C14)/C14*100 -> -6.7589457 | Y14: =(E14-D14)/D14*100 -> -17.04043 | Z14: =(F14-E14)/E14*100 -> -3.6574338 | AA14: =(G14-F14)/F14*100 -> 4.6385259 | AB14: =(H14-G14)/G14*100 -> 19.145521 | AC14: =(I14-H14)/H14*100 -> 18.349315 | AD14: =(J14-I14)/I14*100 -> -53.076769 | AE14: ފްރާންސް | AY14: 5 | AZ14: Germany | BA14: 106381 | BB14: 112109 | BC14: 117532 | BD14: 131561 | BE14: 36435
A15: Germany | B15: 98351 | C15: 93598 | D15: 98328 | E15: 105132 | F15: 106381 | G15: 112109 | H15: 117532 | I15: 131561 | J15: 36435 | L15: =B15/B$7*100 -> 10.266016 | M15: =C15/C$7*100 -> 8.3183286 | N15: =D15/D$7*100 -> 8.1609685 | O15: =E15/E$7*100 -> 8.5178992 | P15: =F15/F$7*100 -> 8.2713712 | Q15: =G15/G$7*100 -> 8.0680541 | R15: =H15/H$7*100 -> 7.9184841 | S15: =I15/I$7*100 -> 7.7257622 | T15: =J15/J$7*100 -> 6.5590267 | V15: 8.6547278 | W15: =(C15-B15)/B15*100 -> -4.8326911 | X15: =(D15-C15)/C15*100 -> 5.0535268 | Y15: =(E15-D15)/D15*100 -> 6.9196973 | Z15: =(F15-E15)/E15*100 -> 1.1880303 | AA15: =(G15-F15)/F15*100 -> 5.3844202 | AB15: =(H15-G15)/G15*100 -> 4.8372566 | AC15: =(I15-H15)/H15*100 -> 11.936324 | AD15: =(J15-I15)/I15*100 -> -72.305622 | AE15: ޖާމަނީ | AY15: 6 | AZ15: China | BA15: 324326 | BB15: 306530 | BC15: 283116 | BD15: 284029 | BE15: 34245
A16: Greece | B16: 2058 | C16: 1841 | D16: 1981 | E16: 1700 | F16: 2077 | G16: 2470 | H16: 2398 | I16: 2805 | J16: 871 | L16: =B16/B$7*100 -> 0.21481694 | M16: =C16/C$7*100 -> 0.16361507 | N16: =D16/D$7*100 -> 0.16441785 | O16: =E16/E$7*100 -> 0.13773569 | P16: =F16/F$7*100 -> 0.1614916 | Q16: =G16/G$7*100 -> 0.17775641 | R16: =H16/H$7*100 -> 0.16156047 | S16: =I16/I$7*100 -> 0.16472027 | T16: =J16/J$7*100 -> 0.15679737 | V16: -31.605184 | W16: =(C16-B16)/B16*100 -> -10.544218 | X16: =(D16-C16)/C16*100 -> 7.6045627 | Y16: =(E16-D16)/D16*100 -> -14.184755 | Z16: =(F16-E16)/E16*100 -> 22.176471 | AA16: =(G16-F16)/F16*100 -> 18.921521 | AB16: =(H16-G16)/G16*100 -> -2.9149798 | AC16: =(I16-H16)/H16*100 -> 16.972477 | AD16: =(J16-I16)/I16*100 -> -68.948307 | AE16: ގްރީސް | AY16: 7 | AZ16: France | BA16: 40487 | BB16: 42365 | BC16: 50476 | BD16: 59738 | BE16: 28031
A17: Hungary | B17: 2408 | C17: 2796 | D17: 3589 | E17: 4436 | F17: 5539 | G17: 6375 | H17: 7782 | I17: 10025 | J17: 5813 | L17: =B17/B$7*100 -> 0.25135043 | M17: =C17/C$7*100 -> 0.24848872 | N17: =D17/D$7*100 -> 0.29787767 | O17: =E17/E$7*100 -> 0.35940913 | P17: =F17/F$7*100 -> 0.43067019 | Q17: =G17/G$7*100 -> 0.45878426 | R17: =H17/H$7*100 -> 0.52429673 | S17: =I17/I$7*100 -> 0.58870612 | T17: =J17/J$7*100 -> 1.0464559 | V17: -7.2419106 | W17: =(C17-B17)/B17*100 -> 16.112957 | X17: =(D17-C17)/C17*100 -> 28.361946 | Y17: =(E17-D17)/D17*100 -> 23.599889 | Z17: =(F17-E17)/E17*100 -> 24.864743 | AA17: =(G17-F17)/F17*100 -> 15.092977 | AB17: =(H17-G17)/G17*100 -> 22.070588 | AC17: =(I17-H17)/H17*100 -> 28.822925 | AD17: =(J17-I17)/I17*100 -> -42.014963 | AE17: ހަންގްރީ | AY17: 8 | AZ17: U.S.A | BA17: 32589 | BB17: 39180 | BC17: 42901 | BD17: 54474 | BE17: 19759
A18: Ireland | B18: 2483 | C18: 2590 | D18: 2759 | E18: 2856 | F18: 3449 | G18: 3892 | H18: 4236 | I18: 4287 | J18: 1688 | L18: =B18/B$7*100 -> 0.25917904 | M18: =C18/C$7*100 -> 0.23018089 | N18: =D18/D$7*100 -> 0.22898983 | O18: =E18/E$7*100 -> 0.23139596 | P18: =F18/F$7*100 -> 0.26816781 | Q18: =G18/G$7*100 -> 0.28009229 | R18: =H18/H$7*100 -> 0.28539205 | S18: =I18/I$7*100 -> 0.25174894 | T18: =J18/J$7*100 -> 0.30387367 | V18: 1.5957447 | W18: =(C18-B18)/B18*100 -> 4.3093033 | X18: =(D18-C18)/C18*100 -> 6.5250965 | Y18: =(E18-D18)/D18*100 -> 3.5157666 | Z18: =(F18-E18)/E18*100 -> 20.763305 | AA18: =(G18-F18)/F18*100 -> 12.844303 | AB18: =(H18-G18)/G18*100 -> 8.8386434 | AC18: =(I18-H18)/H18*100 -> 1.203966 | AD18: =(J18-I18)/I18*100 -> -60.625146 | AE18: އަޔަރލޭންޑް | AY18: 9 | AZ18: Switzerland | BA18: 31678 | BB18: 32651 | BC18: 32984 | BD18: 33829 | BE18: 12517
A19: Israel | B19: 2569 | C19: 3253 | D19: 3299 | E19: 3567 | F19: 5072 | G19: 5949 | H19: 7748 | I19: 10424 | J19: 1782 | L19: =B19/B$7*100 -> 0.26815584 | M19: =C19/C$7*100 -> 0.28910365 | N19: =D19/D$7*100 -> 0.27380843 | O19: =E19/E$7*100 -> 0.28900189 | P19: =F19/F$7*100 -> 0.39435985 | Q19: =G19/G$7*100 -> 0.42812668 | R19: =H19/H$7*100 -> 0.52200604 | S19: =I19/I$7*100 -> 0.61213692 | T19: =J19/J$7*100 -> 0.32079554 | V19: 5.5898068 | W19: =(C19-B19)/B19*100 -> 26.625146 | X19: =(D19-C19)/C19*100 -> 1.4140793 | Y19: =(E19-D19)/D19*100 -> 8.1236738 | Z19: =(F19-E19)/E19*100 -> 42.192318 | AA19: =(G19-F19)/F19*100 -> 17.291009 | AB19: =(H19-G19)/G19*100 -> 30.240377 | AC19: =(I19-H19)/H19*100 -> 34.537945 | AD19: =(J19-I19)/I19*100 -> -82.904835 | AE19: އިޒްރޭލް | AY19: 10 | AZ19: Ukraine | BA19: 7599 | BB19: 9722 | BC19: 11430 | BD19: 13253 | BE19: 10343
A20: Italy | B20: 62782 | C20: 57854 | D20: 57862 | E20: 65616 | F20: 71202 | G20: 88848 | H20: 105297 | I20: 136343 | J20: 46690 | L20: =B20/B$7*100 -> 6.5532737 | M20: =C20/C$7*100 -> 5.1416546 | N20: =D20/D$7*100 -> 4.8023956 | O20: =E20/E$7*100 -> 5.3162736 | P20: =F20/F$7*100 -> 5.5361218 | Q20: =G20/G$7*100 -> 6.3940493 | R20: =H20/H$7*100 -> 7.0941753 | S20: =I20/I$7*100 -> 8.0065794 | T20: =J20/J$7*100 -> 8.4051313 | V20: -24.439149 | W20: =(C20-B20)/B20*100 -> -7.8493836 | X20: =(D20-C20)/C20*100 -> 0.013827912 | Y20: =(E20-D20)/D20*100 -> 13.40085 | Z20: =(F20-E20)/E20*100 -> 8.5131675 | AA20: =(G20-F20)/F20*100 -> 24.783012 | AB20: =(H20-G20)/G20*100 -> 18.513641 | AC20: =(I20-H20)/H20*100 -> 29.484221 | AD20: =(J20-I20)/I20*100 -> -65.755484 | AE20: އިޓަލީ
A21: Netherlands | B21: 6077 | C21: 6453 | D21: 7936 | E21: 9640 | F21: 10372 | G21: 12438 | H21: 13845 | I21: 12261 | J21: 3258 | L21: =B21/B$7*100 -> 0.63432583 | M21: =C21/C$7*100 -> 0.57349703 | N21: =D21/D$7*100 -> 0.65866738 | O21: =E21/E$7*100 -> 0.78104238 | P21: =F21/F$7*100 -> 0.80644722 | Q21: =G21/G$7*100 -> 0.89511508 | R21: =H21/H$7*100 -> 0.93277926 | S21: =I21/I$7*100 -> 0.72001254 | T21: =J21/J$7*100 -> 0.58650498 | V21: 6.7451256 | W21: =(C21-B21)/B21*100 -> 6.1872635 | X21: =(D21-C21)/C21*100 -> 22.981559 | Y21: =(E21-D21)/D21*100 -> 21.471774 | Z21: =(F21-E21)/E21*100 -> 7.593361 | AA21: =(G21-F21)/F21*100 -> 19.919013 | AB21: =(H21-G21)/G21*100 -> 11.312108 | AC21: =(I21-H21)/H21*100 -> -11.440953 | AD21: =(J21-I21)/I21*100 -> -73.427942 | AE21: ނެދަރލޭންޑްސް
A22: Norway | B22: 2902 | C22: 3281 | D22: 3882 | E22: 4153 | F22: 3971 | G22: 5006 | H22: 5585 | I22: 5641 | J22: 1624 | L22: =B22/B$7*100 -> 0.30291485 | M22: =C22/C$7*100 -> 0.29159209 | N22: =D22/D$7*100 -> 0.32219591 | O22: =E22/E$7*100 -> 0.33648019 | P22: =F22/F$7*100 -> 0.30875452 | Q22: =G22/G$7*100 -> 0.36026259 | R22: =H22/H$7*100 -> 0.37627823 | S22: =I22/I$7*100 -> 0.33126097 | T22: =J22/J$7*100 -> 0.29235239 | V22: 4.5765766 | W22: =(C22-B22)/B22*100 -> 13.059959 | X22: =(D22-C22)/C22*100 -> 18.317586 | Y22: =(E22-D22)/D22*100 -> 6.9809377 | Z22: =(F22-E22)/E22*100 -> -4.3823742 | AA22: =(G22-F22)/F22*100 -> 26.063964 | AB22: =(H22-G22)/G22*100 -> 11.566121 | AC22: =(I22-H22)/H22*100 -> 1.0026858 | AD22: =(J22-I22)/I22*100 -> -71.210778 | AE22: ނޯރވޭ
A23: Poland | B23: 3918 | C23: 6668 | D23: 6182 | E23: 6879 | F23: 8976 | G23: 8699 | H23: 12025 | I23: 20961 | J23: 7108 | L23: =B23/B$7*100 -> 0.40896636 | M23: =C23/C$7*100 -> 0.59260471 | N23: =D23/D$7*100 -> 0.51308994 | O23: =E23/E$7*100 -> 0.55734342 | P23: =F23/F$7*100 -> 0.69790496 | Q23: =G23/G$7*100 -> 0.62603361 | R23: =H23/H$7*100 -> 0.81016039 | S23: =I23/I$7*100 -> 1.2309096 | T23: =J23/J$7*100 -> 1.2795818 | V23: -5.7720058 | W23: =(C23-B23)/B23*100 -> 70.188872 | X23: =(D23-C23)/C23*100 -> -7.2885423 | Y23: =(E23-D23)/D23*100 -> 11.274668 | Z23: =(F23-E23)/E23*100 -> 30.484082 | AA23: =(G23-F23)/F23*100 -> -3.0860071 | AB23: =(H23-G23)/G23*100 -> 38.23428 | AC23: =(I23-H23)/H23*100 -> 74.31185 | AD23: =(J23-I23)/I23*100 -> -66.089404 | AE23: ޕޮލޭންޑް
A24: Portugal | B24: 3660 | C24: 4617 | D24: 4916 | E24: 5057 | F24: 6259 | G24: 6882 | H24: 8342 | I24: 11428 | J24: 3206 | L24: =B24/B$7*100 -> 0.38203596 | M24: =C24/C$7*100 -> 0.41032632 | N24: =D24/D$7*100 -> 0.40801523 | O24: =E24/E$7*100 -> 0.40972317 | P24: =F24/F$7*100 -> 0.48665187 | Q24: =G24/G$7*100 -> 0.4952711 | R24: =H24/H$7*100 -> 0.56202561 | S24: =I24/I$7*100 -> 0.67109562 | T24: =J24/J$7*100 -> 0.57714395 | V24: -17.456022 | W24: =(C24-B24)/B24*100 -> 26.147541 | X24: =(D24-C24)/C24*100 -> 6.4760667 | Y24: =(E24-D24)/D24*100 -> 2.8681855 | Z24: =(F24-E24)/E24*100 -> 23.769033 | AA24: =(G24-F24)/F24*100 -> 9.9536667 | AB24: =(H24-G24)/G24*100 -> 21.214763 | AC24: =(I24-H24)/H24*100 -> 36.993527 | AD24: =(J24-I24)/I24*100 -> -71.946097 | AE24: ޕޯޗުގަލް
A25: Russia | B25: 66378 | C25: 76479 | D25: 66308 | E25: 44323 | F25: 46522 | G25: 61931 | H25: 70935 | I25: 83369 | J25: 61387 | L25: =B25/B$7*100 -> 6.9286292 | M25: =C25/C$7*100 -> 6.7969129 | N25: =D25/D$7*100 -> 5.5033917 | O25: =E25/E$7*100 -> 3.5910935 | P25: =F25/F$7*100 -> 3.6171942 | Q25: =G25/G$7*100 -> 4.4569362 | R25: =H25/H$7*100 -> 4.7791041 | S25: =I25/I$7*100 -> 4.8957447 | T25: =J25/J$7*100 -> 11.050884 | V25: 3.8194444 | W25: =(C25-B25)/B25*100 -> 15.217391 | X25: =(D25-C25)/C25*100 -> -13.299076 | Y25: =(E25-D25)/D25*100 -> -33.155879 | Z25: =(F25-E25)/E25*100 -> 4.9613068 | AA25: =(G25-F25)/F25*100 -> 33.121964 | AB25: =(H25-G25)/G25*100 -> 14.538761 | AC25: =(I25-H25)/H25*100 -> 17.528723 | AD25: =(J25-I25)/I25*100 -> -26.367115 | AE25: ރަޝިއާ
A26: Slovakia | B26: 2636 | C26: 2758 | D26: 3262 | E26: 4286 | F26: 4957 | G26: 6079 | H26: 6584 | I26: 6910 | J26: 4498 | L26: =B26/B$7*100 -> 0.2751494 | M26: =C26/C$7*100 -> 0.24511154 | N26: =D26/D$7*100 -> 0.27073752 | O26: =E26/E$7*100 -> 0.34725598 | P26: =F26/F$7*100 -> 0.38541833 | Q26: =G26/G$7*100 -> 0.43748228 | R26: =H26/H$7*100 -> 0.44358387 | S26: =I26/I$7*100 -> 0.40578148 | T26: =J26/J$7*100 -> 0.80972972 | V26: -6.5910702 | W26: =(C26-B26)/B26*100 -> 4.6282246 | X26: =(D26-C26)/C26*100 -> 18.274112 | Y26: =(E26-D26)/D26*100 -> 31.391784 | Z26: =(F26-E26)/E26*100 -> 15.655623 | AA26: =(G26-F26)/F26*100 -> 22.634658 | AB26: =(H26-G26)/G26*100 -> 8.3072874 | AC26: =(I26-H26)/H26*100 -> 4.9513973 | AD26: =(J26-I26)/I26*100 -> -34.905933 | AE26: ސްލޮވޭކިއާ
A27: Slovenia | B27: 1295 | C27: 1243 | D27: 1319 | E27: 1470 | F27: 1548 | G27: 2100 | H27: 3167 | I27: 3693 | J27: 1561 | L27: =B27/B$7*100 -> 0.13517393 | M27: =C27/C$7*100 -> 0.11046905 | N27: =D27/D$7*100 -> 0.10947357 | O27: =E27/E$7*100 -> 0.11910086 | P27: =F27/F$7*100 -> 0.12036062 | Q27: =G27/G$7*100 -> 0.15112893 | R27: =H27/H$7*100 -> 0.21337031 | S27: =I27/I$7*100 -> 0.216867 | T27: =J27/J$7*100 -> 0.28101114 | V27: -19.515227 | W27: =(C27-B27)/B27*100 -> -4.015444 | X27: =(D27-C27)/C27*100 -> 6.1142397 | Y27: =(E27-D27)/D27*100 -> 11.448067 | Z27: =(F27-E27)/E27*100 -> 5.3061224 | AA27: =(G27-F27)/F27*100 -> 35.658915 | AB27: =(H27-G27)/G27*100 -> 50.809524 | AC27: =(I27-H27)/H27*100 -> 16.608778 | AD27: =(J27-I27)/I27*100 -> -57.730842 | AE27: ސްލްވީނިއާ
A28: Spain | B28: 8824 | C28: 11040 | D28: 15230 | E28: 17816 | F28: 23393 | G28: 25843 | H28: 31780 | I28: 36064 | J28: 6778 | L28: =B28/B$7*100 -> 0.92106156 | M28: =C28/C$7*100 -> 0.98115716 | N28: =D28/D$7*100 -> 1.2640504 | O28: =E28/E$7*100 -> 1.44347 | P28: =F28/F$7*100 -> 1.8188604 | Q28: =G28/G$7*100 -> 1.8598214 | R28: =H28/H$7*100 -> 2.1411141 | S28: =I28/I$7*100 -> 2.1178152 | T28: =J28/J$7*100 -> 1.2201752 | V28: -9.1246138 | W28: =(C28-B28)/B28*100 -> 25.113327 | X28: =(D28-C28)/C28*100 -> 37.952899 | Y28: =(E28-D28)/D28*100 -> 16.979645 | Z28: =(F28-E28)/E28*100 -> 31.303323 | AA28: =(G28-F28)/F28*100 -> 10.473218 | AB28: =(H28-G28)/G28*100 -> 22.973339 | AC28: =(I28-H28)/H28*100 -> 13.480176 | AD28: =(J28-I28)/I28*100 -> -81.205634 | AE28: ސްޕެއިން
A29: Sweden | B29: 5230 | C29: 5694 | D29: 7163 | E29: 9138 | F29: 10918 | G29: 13127 | H29: 14988 | I29: 13245 | J29: 5613 | L29: =B29/B$7*100 -> 0.54591477 | M29: =C29/C$7*100 -> 0.50604247 | N29: =D29/D$7*100 -> 0.59451039 | O29: =E29/E$7*100 -> 0.74036984 | P29: =F29/F$7*100 -> 0.8489 | Q29: =G29/G$7*100 -> 0.94469976 | R29: =H29/H$7*100 -> 1.0097866 | S29: =I29/I$7*100 -> 0.77779677 | T29: =J29/J$7*100 -> 1.010452 | V29: 6.8218954 | W29: =(C29-B29)/B29*100 -> 8.8718929 | X29: =(D29-C29)/C29*100 -> 25.799087 | Y29: =(E29-D29)/D29*100 -> 27.572246 | Z29: =(F29-E29)/E29*100 -> 19.479098 | AA29: =(G29-F29)/F29*100 -> 20.232643 | AB29: =(H29-G29)/G29*100 -> 14.176887 | AC29: =(I29-H29)/H29*100 -> -11.629303 | AD29: =(J29-I29)/I29*100 -> -57.621744 | AE29: ސްވިޑްން
A30: Switzerland | B30: 35457 | C30: 34102 | D30: 31497 | E30: 31923 | F30: 31678 | G30: 32651 | H30: 32984 | I30: 33829 | J30: 12517 | L30: =B30/B$7*100 -> 3.7010516 | M30: =C30/C$7*100 -> 3.0307447 | N30: =D30/D$7*100 -> 2.6141692 | O30: =E30/E$7*100 -> 2.5864332 | P30: =F30/F$7*100 -> 2.4630385 | Q30: =G30/G$7*100 -> 2.349767 | R30: =H30/H$7*100 -> 2.2222312 | S30: =I30/I$7*100 -> 1.9865675 | T30: =J30/J$7*100 -> 2.2533097 | V30: 9.0850357 | W30: =(C30-B30)/B30*100 -> -3.8215303 | X30: =(D30-C30)/C30*100 -> -7.6388482 | Y30: =(E30-D30)/D30*100 -> 1.3525098 | Z30: =(F30-E30)/E30*100 -> -0.76747173 | AA30: =(G30-F30)/F30*100 -> 3.0715323 | AB30: =(H30-G30)/G30*100 -> 1.0198769 | AC30: =(I30-H30)/H30*100 -> 2.5618482 | AD30: =(J30-I30)/I30*100 -> -62.999202 | AE30: ސްވިޓްޒަރލޭންޑް
A31: Turkey | B31: 5416 | C31: 9117 | D31: 8668 | E31: 10200 | F31: 10091 | G31: 11168 | H31: 10129 | I31: 9976 | J31: 3164 | L31: =B31/B$7*100 -> 0.56532971 | M31: =C31/C$7*100 -> 0.81025451 | N31: =D31/D$7*100 -> 0.71942147 | O31: =E31/E$7*100 -> 0.82641414 | P31: =F31/F$7*100 -> 0.78459882 | Q31: =G31/G$7*100 -> 0.80371806 | R31: =H31/H$7*100 -> 0.68242117 | S31: =I31/I$7*100 -> 0.58582865 | T31: =J31/J$7*100 -> 0.56958311 | V31: 19.242624 | W31: =(C31-B31)/B31*100 -> 68.334564 | X31: =(D31-C31)/C31*100 -> -4.9248656 | Y31: =(E31-D31)/D31*100 -> 17.674204 | Z31: =(F31-E31)/E31*100 -> -1.0686275 | AA31: =(G31-F31)/F31*100 -> 10.672877 | AB31: =(H31-G31)/G31*100 -> -9.3033668 | AC31: =(I31-H31)/H31*100 -> -1.5105144 | AD31: =(J31-I31)/I31*100 -> -68.283881 | AE31: ޓަރކީ
... A34: Other Europe | B34: 18612 | C34: 18036 | D34: 17044 | E34: 23361 | F34: 26943 | G34: 33356 | H34: 37628 | I34: 43424 | J34: 28890 | L34: =B34/B$7*100 -> 1.9427468 | M34: =C34/C$7*100 -> 1.6029122 | N34: =D34/D$7*100 -> 1.4146077 | O34: =E34/E$7*100 -> 1.8927314 | P34: =F34/F$7*100 -> 2.0948812 | Q34: =G34/G$7*100 -> 2.4005032 | R34: =H34/H$7*100 -> 2.5351114 | S34: =I34/I$7*100 -> 2.5500224 | T34: =J34/J$7*100 -> 5.2007762 | V34: 53.97088 | W34: =(C34-B34)/B34*100 -> -3.0947776 | X34: =(D34-C34)/C34*100 -> -5.5001109 | Y34: =(E34-D34)/D34*100 -> 37.062896 | Z34: =(F34-E34)/E34*100 -> 15.333248 | AA34: =(G34-F34)/F34*100 -> 23.802101 | AB34: =(H34-G34)/G34*100 -> 12.807291 | AC34: =(I34-H34)/H34*100 -> 15.403423 | AD34: =(J34-I34)/I34*100 -> -33.469971 | AE34: އެހެނިހެން
A35: Asia | B35: =SUM(B36:B49) -> 367680 | C35: =SUM(C36:C49) -> 505753 | D35: =SUM(D36:D49) -> 568031 | E35: =SUM(E36:E49) -> 578322 | F35: =SUM(F36:F49) -> 572336 | G35: =SUM(G36:G49) -> 586791 | H35: =SUM(H36:H49) -> 580928 | I35: =SUM(I36:I49) -> 661000 | J35: =SUM(J36:J49) -> 134279 | L35: =B35/B$7*100 -> 38.378957 | M35: =C35/C$7*100 -> 44.947752 | N35: =D35/D$7*100 -> 47.145097 | O35: =E35/E$7*100 -> 46.856223 | P35: =F35/F$7*100 -> 44.500461 | Q35: =G35/G$7*100 -> 42.229094 | R35: =H35/H$7*100 -> 39.138865 | S35: =I35/I$7*100 -> 38.816434 | T35: =J35/J$7*100 -> 24.172898 | V35: 9.856226 | W35: =(C35-B35)/B35*100 -> 37.552491 | X35: =(D35-C35)/C35*100 -> 12.313916 | Y35: =(E35-D35)/D35*100 -> 1.8116969 | Z35: =(F35-E35)/E35*100 -> -1.0350635 | AA35: =(G35-F35)/F35*100 -> 2.5256143 | AB35: =(H35-G35)/G35*100 -> -0.99916325 | AC35: =(I35-H35)/H35*100 -> 13.783464 | AD35: =(J35-I35)/I35*100 -> -79.685477 | AE35: އޭޝިއާ
A36: Bangladesh | B36: 1221 | C36: 1906 | D36: 2231 | E36: 4431 | F36: 6018 | G36: 4714 | H36: 3644 | I36: 3918 | J36: 1108 | L36: =B36/B$7*100 -> 0.1274497 | M36: =C36/C$7*100 -> 0.16939181 | N36: =D36/D$7*100 -> 0.1851672 | O36: =E36/E$7*100 -> 0.35900403 | P36: =F36/F$7*100 -> 0.46791355 | Q36: =G36/G$7*100 -> 0.33924847 | R36: =H36/H$7*100 -> 0.24550723 | S36: =I36/I$7*100 -> 0.23007986 | T36: =J36/J$7*100 -> 0.1994621 | V36: -18.382353 | W36: =(C36-B36)/B36*100 -> 56.101556 | X36: =(D36-C36)/C36*100 -> 17.051417 | Y36: =(E36-D36)/D36*100 -> 98.610489 | Z36: =(F36-E36)/E36*100 -> 35.815843 | AA36: =(G36-F36)/F36*100 -> -21.668328 | AB36: =(H36-G36)/G36*100 -> -22.698345 | AC36: =(I36-H36)/H36*100 -> 7.5192097 | AD36: =(J36-I36)/I36*100 -> -71.720265 | AE36: ބަންގްލަދޭޝް
A37: China | B37: 229551 | C37: 331719 | D37: 363626 | E37: 359514 | F37: 324326 | G37: 306530 | H37: 283116 | I37: 284029 | J37: 34245 | L37: =B37/B$7*100 -> 23.960857 | M37: =C37/C$7*100 -> 29.48084 | N37: =D37/D$7*100 -> 30.180013 | O37: =E37/E$7*100 -> 29.128182 | P37: =F37/F$7*100 -> 25.217104 | Q37: =G37/G$7*100 -> 22.059787 | R37: =H37/H$7*100 -> 19.074376 | S37: =I37/I$7*100 -> 16.679263 | T37: =J37/J$7*100 -> 6.1647831 | V37: 15.552591 | W37: =(C37-B37)/B37*100 -> 44.507756 | X37: =(D37-C37)/C37*100 -> 9.6186833 | Y37: =(E37-D37)/D37*100 -> -1.1308322 | Z37: =(F37-E37)/E37*100 -> -9.7876578 | AA37: =(G37-F37)/F37*100 -> -5.4870717 | AB37: =(H37-G37)/G37*100 -> -7.6384041 | AC37: =(I37-H37)/H37*100 -> 0.32248266 | AD37: =(J37-I37)/I37*100 -> -87.943133 | AE37: ޗައިނާ
A38: India | B38: 31721 | C38: 38014 | D38: 45587 | E38: 52368 | F38: 66955 | G38: 83019 | H38: 90474 | I38: 166030 | J38: 62960 | L38: =B38/B$7*100 -> 3.3110827 | M38: =C38/C$7*100 -> 3.3784156 | N38: =D38/D$7*100 -> 3.7836025 | O38: =E38/E$7*100 -> 4.2429074 | P38: =F38/F$7*100 -> 5.2059076 | Q38: =G38/G$7*100 -> 5.9745585 | R38: =H38/H$7*100 -> 6.0955053 | S38: =I38/I$7*100 -> 9.7499129 | T38: =J38/J$7*100 -> 11.334056 | V38: 2.3984763 | W38: =(C38-B38)/B38*100 -> 19.838593 | X38: =(D38-C38)/C38*100 -> 19.921608 | Y38: =(E38-D38)/D38*100 -> 14.874855 | Z38: =(F38-E38)/E38*100 -> 27.854797 | AA38: =(G38-F38)/F38*100 -> 23.992234 | AB38: =(H38-G38)/G38*100 -> 8.9798721 | AC38: =(I38-H38)/H38*100 -> 83.511285 | AD38: =(J38-I38)/I38*100 -> -62.079142 | AE38: އިންޑިއާ
A39: Indonesia | B39: 1772 | C39: 2511 | D39: 3333 | E39: 3452 | F39: 4886 | G39: 5375 | H39: 5885 | I39: 4646 | J39: 857 | L39: =B39/B$7*100 -> 0.18496386 | M39: =C39/C$7*100 -> 0.22315993 | N39: =D39/D$7*100 -> 0.27663034 | O39: =E39/E$7*100 -> 0.27968447 | P39: =F39/F$7*100 -> 0.37989791 | Q39: =G39/G$7*100 -> 0.3868181 | R39: =H39/H$7*100 -> 0.39649014 | S39: =I39/I$7*100 -> 0.27283079 | T39: =J39/J$7*100 -> 0.15427709 | V39: 38.113796 | W39: =(C39-B39)/B39*100 -> 41.704289 | X39: =(D39-C39)/C39*100 -> 32.735962 | Y39: =(E39-D39)/D39*100 -> 3.570357 | Z39: =(F39-E39)/E39*100 -> 41.541136 | AA39: =(G39-F39)/F39*100 -> 10.008187 | AB39: =(H39-G39)/G39*100 -> 9.4883721 | AC39: =(I39-H39)/H39*100 -> -21.053526 | AD39: =(J39-I39)/I39*100 -> -81.554025 | AE39: އިންޑޮނޭޝިއާ
A40: Japan | B40: 36438 | C40: 39463 | D40: 38817 | E40: 39244 | F40: 39894 | G40: 41133 | H40: 42304 | I40: 44251 | J40: 8479 | L40: =B40/B$7*100 -> 3.8034498 | M40: =C40/C$7*100 -> 3.5071925 | N40: =D40/D$7*100 -> 3.2217101 | O40: =E40/E$7*100 -> 3.1795879 | P40: =F40/F$7*100 -> 3.1018517 | Q40: =G40/G$7*100 -> 2.960184 | R40: =H40/H$7*100 -> 2.8501476 | S40: =I40/I$7*100 -> 2.598587 | T40: =J40/J$7*100 -> 1.5263891 | V40: 1.833324 | W40: =(C40-B40)/B40*100 -> 8.3017729 | X40: =(D40-C40)/C40*100 -> -1.6369764 | Y40: =(E40-D40)/D40*100 -> 1.1000335 | Z40: =(F40-E40)/E40*100 -> 1.6563041 | AA40: =(G40-F40)/F40*100 -> 3.1057302 | AB40: =(H40-G40)/G40*100 -> 2.8468626 | AC40: =(I40-H40)/H40*100 -> 4.6024017 | AD40: =(J40-I40)/I40*100 -> -80.838851 | AE40: ޖަޕާން
A41: Korea | B41: 23933 | C41: 30306 | D41: 34896 | E41: 33001 | F41: 29580 | G41: 34808 | H41: 34400 | I41: 37073 | J41: 5895 | L41: =B41/B$7*100 -> 2.4981603 | M41: =C41/C$7*100 -> 2.6933831 | N41: =D41/D$7*100 -> 2.8962773 | O41: =E41/E$7*100 -> 2.6737738 | P41: =F41/F$7*100 -> 2.2999141 | Q41: =G41/G$7*100 -> 2.504998 | R41: =H41/H$7*100 -> 2.3176314 | S41: =I41/I$7*100 -> 2.1770675 | T41: =J41/J$7*100 -> 1.0612176 | V41: -5.3470437 | W41: =(C41-B41)/B41*100 -> 26.628505 | X41: =(D41-C41)/C41*100 -> 15.145516 | Y41: =(E41-D41)/D41*100 -> -5.4304218 | Z41: =(F41-E41)/E41*100 -> -10.366353 | AA41: =(G41-F41)/F41*100 -> 17.674104 | AB41: =(H41-G41)/G41*100 -> -1.1721443 | AC41: =(I41-H41)/H41*100 -> 7.7703488 | AD41: =(J41-I41)/I41*100 -> -84.09894 | AE41: ކޮރެއާ
A42: Malaysia | B42: 6766 | C42: 10875 | D42: 13457 | E42: 12575 | F42: 16185 | G42: 19092 | H42: 22202 | I42: 21605 | J42: 2946 | L42: =B42/B$7*100 -> 0.70624462 | M42: =C42/C$7*100 -> 0.96649313 | N42: =D42/D$7*100 -> 1.116896 | O42: =E42/E$7*100 -> 1.018839 | P42: =F42/F$7*100 -> 1.2584215 | Q42: =G42/G$7*100 -> 1.3739779 | R42: =H42/H$7*100 -> 1.4958155 | S42: =I42/I$7*100 -> 1.2687278 | T42: =J42/J$7*100 -> 0.53033876 | V42: 11.742362 | W42: =(C42-B42)/B42*100 -> 60.730121 | X42: =(D42-C42)/C42*100 -> 23.742529 | Y42: =(E42-D42)/D42*100 -> -6.5542097 | Z42: =(F42-E42)/E42*100 -> 28.707753 | AA42: =(G42-F42)/F42*100 -> 17.961075 | AB42: =(H42-G42)/G42*100 -> 16.289545 | AC42: =(I42-H42)/H42*100 -> -2.6889469 | AD42: =(J42-I42)/I42*100 -> -86.364268 | AE42: މެލޭޝިއާ
A43: Pakistan | B43: 1857 | C43: 2693 | D43: 3105 | E43: 3987 | F43: 6251 | G43: 6241 | H43: 5340 | I43: 6095 | J43: 2882 | L43: =B43/B$7*100 -> 0.19383628 | M43: =C43/C$7*100 -> 0.2393348 | N43: =D43/D$7*100 -> 0.25770693 | O43: =E43/E$7*100 -> 0.3230307 | P43: =F43/F$7*100 -> 0.48602985 | Q43: =G43/G$7*100 -> 0.4491408 | R43: =H43/H$7*100 -> 0.35977185 | S43: =I43/I$7*100 -> 0.35792158 | T43: =J43/J$7*100 -> 0.51881748 | V43: 0.81433225 | W43: =(C43-B43)/B43*100 -> 45.018848 | X43: =(D43-C43)/C43*100 -> 15.298923 | Y43: =(E43-D43)/D43*100 -> 28.405797 | Z43: =(F43-E43)/E43*100 -> 56.78455 | AA43: =(G43-F43)/F43*100 -> -0.1599744 | AB43: =(H43-G43)/G43*100 -> -14.436789 | AC43: =(I43-H43)/H43*100 -> 14.138577 | AD43: =(J43-I43)/I43*100 -> -52.71534 | AE43: ޕާކިސްތާން
...

Sheet 10.2
A1: 2020- 2012 ,udwdwA egunwt iaWawlcmuj egiawgWj egudnea WviawfcSokIrwTcsijwr cnutwvWb egunwtcnwt Wviawfihejwmwh cmWzitcnia egumubit cnirevurutwf : 10.2 ulwvWt
A2: Table 10.2 : TOTAL REGISTERED BED CAPACITY AND NUMBER OF ACCOMMODATION ESTABLISHMENTS, BY TYPE, 2012 - 2020 (end year)
A3: Type | B3: 2002 | C3: 2005 | D3: 2006 | F3: 2007 | H3: 2008 | J3: 2009 | K3: 2010 | L3: 2011 | M3: 2012 | N3: 2013 | O3: 2014 | P3: 2015 | Q3: 2016 | R3: 2017 | S3: 2018 | T3: 2019 | U3: 2020 | V3: ctwvWbegunwt
A5: Number of Beds (Registered) | V5: wgWj egudnea WviawfcSok IrcTcsijwr
A6: Total | B6: 18827 | C6: =SUM(C7:C10) -> 20198 | D6: =SUM(D7:D10) -> 20505 | F6: =SUM(F7:F10) -> 22187 | H6: =SUM(H7:H10) -> 23464 | J6: =SUM(J7:J10) -> 24978 | K6: =SUM(K7:K10) -> 25709 | L6: =SUM(L7:L10) -> 26896 | M6: =SUM(M7:M10) -> 28120 | N6: =SUM(N7:N10) -> 29829 | O6: =SUM(O7:O10) -> 31673 | P6: =SUM(P7:P10) -> 34085 | Q6: =SUM(Q7:Q10) -> 37374 | ... U6: =SUM(U7:U10) -> 52341.083 | V6: wlcmuj
A7: Resorts (including Marinas) | B7: 16400 | C7: 17348 | D7: 17802 | F7: 19028 | H7: 19860 | J7: 20942 | K7: 21350 | L7: 22120 | M7: 22889 | N7: 23487 | O7: 24031 | P7: 24877 | Q7: 26933 | R7: 29977 | S7: 31971 | T7: 37004 | U7: 37566.333 | V7: ރިސޯޓްތައް (މެރީނާއާއި އެކު)
A8: Hotels | B8: 670 | C8: 636 | D8: 713 | F8: 836 | H8: 1110 | J8: 1368 | K8: 1449 | L8: 1603 | M8: 1627 | N8: 1708 | O8: 1704 | P8: 1648 | Q8: 1713 | R8: 1456 | S8: 1862 | T8: 1642 | U8: 1698 | V8: cawtWToh
A9: Guest Houses | B9: 282 | C9: 425 | D9: 391 | F9: 400 | H9: 400 | J9: 462 | K9: 476 | L9: 659 | M9: 1101 | N9: 1918 | O9: 3199 | P9: 4621 | Q9: 6034 | R9: 7304 | S9: 8563 | T9: 9753 | U9: 10154.333 | V9: cawtegIluk
A10: Safari Vessels | B10: 1475 | C10: 1789 | D10: 1599 | F10: 1923 | H10: 2094 | J10: 2206 | K10: 2434 | L10: 2514 | M10: 2503 | N10: 2716 | O10: 2739 | P10: 2939 | Q10: 2694 | R10: 2518 | S10: 2758 | T10: 2963 | U10: 2922.4167 | V10: cawtudnwLua
A11: No. of Beds in operation 1_/ | V11: ބޭނުންކުރެވުނު އެނދުގެ އަދަދު
A12: Total | B12: 18827 | C12: =SUM(C13:C16) -> 20198 | D12: =SUM(D13:D16) -> 20505 | F12: =SUM(F13:F16) -> 22187 | H12: - | J12: - | K12: - | L12: - | M12: =SUM(M13:M16) -> 26798.167 | N12: =SUM(N13:N16) -> 27997.917 | O12: =SUM(O13:O16) -> 29515.25 | P12: =SUM(P13:P16) -> 31423.917 | Q12: =SUM(Q13:Q16) -> 33802.25 | R12: =SUM(R13:R16) -> 38592.333 | S12: =SUM(S13:S16) -> 41886.667 | T12: =SUM(T13:T16) -> 47268.5 | U12: =SUM(U13:U16) -> 27744.667 | V12: wlcmuj
A13: Resorts (including Marinas) | B13: 16400 | C13: 17348 | D13: 17802 | F13: 19028 | H13: - | J13: - | K13: - | L13: - | M13: 21887.833 | N13: 22511.833 | O13: 22986.167 | P13: 23348.417 | Q13: 24567.667 | R13: 27685.917 | S13: 29399.667 | T13: 33439.75 | U13: 21445.667 | V13: ރިސޯޓްތައް (މެރީނާއާއި އެކު)
A14: Hotels | B14: 670 | C14: 636 | D14: 713 | F14: 836 | H14: - | J14: - | K14: - | L14: - | M14: 1591.3333 | N14: 1540.0833 | O14: 1435.25 | P14: 1456.1667 | Q14: 1465.5 | R14: 1496.8333 | S14: 1759 | T14: 1723 | U14: 1032.5 | V14: cawtWToh
A15: Guest Houses | B15: 282 | C15: 425 | D15: 391 | F15: 400 | H15: - | J15: - | K15: - | L15: - | M15: 844.5 | N15: 1401.5833 | O15: 2477.25 | P15: 3831.1667 | Q15: 5248.9167 | R15: 6728.8333 | S15: 8000 | T15: 9200.1667 | U15: 3615.0833 | V15: cawtegIluk
A16: Safari Vessels | B16: 1475 | C16: 1789 | D16: 1599 | F16: 1923 | H16: - | J16: - | K16: - | L16: - | M16: 2474.5 | N16: 2544.4167 | O16: 2616.5833 | P16: 2788.1667 | Q16: 2520.1667 | R16: 2680.75 | S16: 2728 | T16: 2905.5833 | U16: 1651.4167 | V16: cawtudnwLua
A17: No. of Establishments (Registered) | V17: ރެޖިސްޓްރީ ކުރެވިފައިވާ ތަންތަނުގެ އަދަދު
A18: Total | B18: 208 | C18: =SUM(C19:C22) -> 245 | D18: =SUM(D19:D22) -> 235 | F18: =SUM(F19:F22) -> 260 | H18: =SUM(H19:H22) -> 274 | I18: =SUM(I19:I22) -> 0 | J18: =SUM(J19:J22) -> 278 | K18: =SUM(K19:K22) -> 295 | L18: =SUM(L19:L22) -> 315 | M18: =SUM(M19:M22) -> 353 | N18: =SUM(N19:N22) -> 429 | O18: =SUM(O19:O22) -> 511 | ... U18: =SUM(U19:U22) -> 952 | V18: wlcmuj
A19: Resorts (including Marinas) | B19: 87 | C19: 88 | D19: 89 | F19: 92 | H19: 94 | J19: 97 | K19: 97 | L19: 101 | M19: 105 | N19: 110 | O19: 111 | P19: 115 | Q19: 126 | R19: 135 | S19: 145 | T19: 164 | U19: 159 | V19: ރިސޯޓްތައް (މެރީނާއާއި އެކު)
A20: Hotels | B20: 8 | C20: 8 | D20: 9 | F20: 11 | H20: 13 | J20: 14 | K20: 17 | L20: 19 | M20: 19 | N20: 20 | O20: 19 | P20: 17 | Q20: 16 | R20: 10 | S20: 12 | T20: 12 | U20: 13 | V20: cawtWToh
A21: Guest Houses | B21: 17 | C21: 28 | D21: 21 | F21: 24 | H21: 24 | J21: 22 | K21: 25 | L21: 38 | M21: 75 | N21: 136 | O21: 220 | P21: 313 | Q21: 393 | R21: 458 | S21: 521 | T21: 605 | U21: 638 | V21: cawtegIluk
A22: Safari Vessels | B22: 96 | C22: 121 | D22: 116 | F22: 133 | H22: 143 | J22: 145 | K22: 156 | L22: 157 | M22: 154 | N22: 163 | O22: 161 | P22: 170 | Q22: 144 | R22: 133 | S22: 147 | T22: 157 | U22: 142 | V22: cawtudnwLua
A23: No. Establishmentss in operation | V23: ބޭނުންކުރެވުނު ތަންތަނުގެ އަދަދު
A24: Total | B24: 18827 | C24: =SUM(C25:C28) -> 20198 | D24: =SUM(D25:D28) -> 20505 | F24: =SUM(F25:F28) -> 22187 | H24: - | J24: - | K24: - | L24: - | M24: =SUM(M25:M28) -> 323.08333 | N24: =SUM(N25:N28) -> 370.33333 | O24: =SUM(O25:O28) -> 448.16667 | P24: =SUM(P25:P28) -> 540.33333 | Q24: =SUM(Q25:Q28) -> 611.41667 | R24: =SUM(R25:R28) -> 713.41667 | S24: =SUM(S25:S28) -> 777 | T24: =SUM(T25:T28) -> 872.16667 | U24: =SUM(U25:U28) -> 550 | V24: wlcmuj
A25: Resorts (including Marinas) | B25: 16400 | C25: 17348 | D25: 17802 | F25: 19028 | H25: - | J25: - | K25: - | L25: - | M25: 97.666667 | N25: 101.08333 | O25: 104.41667 | P25: 104.83333 | Q25: 111.08333 | R25: 124.08333 | S25: 130 | T25: 146 | U25: 140 | V25: ރިސޯޓްތައް (މެރީނާއާއި އެކު)
A26: Hotels | B26: 670 | C26: 636 | D26: 713 | F26: 836 | H26: - | J26: - | K26: - | L26: - | M26: 18.583333 | N26: 17.333333 | O26: 15.583333 | P26: 14.333333 | Q26: 12.666667 | R26: 11.916667 | S26: 12 | T26: 11.416667 | U26: 11 | V26: cawtWToh
A27: Guest Houses | B27: 282 | C27: 425 | D27: 391 | F27: 400 | H27: - | J27: - | K27: - | L27: - | M27: 54.333333 | N27: 98.833333 | O27: 172.91667 | P27: 261.66667 | Q27: 353.5 | R27: 433.58333 | S27: 490 | T27: 561 | U27: 268 | V27: cawtegIluk
A28: Safari Vessels | B28: 1475 | C28: 1789 | D28: 1599 | F28: 1923 | H28: - | J28: - | K28: - | L28: - | M28: 152.5 | N28: 153.08333 | O28: 155.25 | P28: 159.5 | Q28: 134.16667 | R28: 143.83333 | S28: 145 | T28: 153.75 | U28: 131 | V28: cawtudnwLua
A29: Bed capacity utilization rate (%) | V29: އެނދުގެ ޖާގައިން ބޭނުންކުރެވުނު މިންވަރު %
A30: Resorts (including Marinas) | B30: 87 | C30: 88 | D30: 89 | F30: 92 | H30: - | J30: - | K30: - | L30: - | M30: 86.68877 | N30: 88.595127 | O30: 81.856214 | P30: 76.220607 | Q30: 73.996437 | R30: 72.738666 | S30: 74.6 | T30: 74.139743 | U30: 28.978641 | V30: ރިސޯޓްތައް (މެރީނާއާއި އެކު)
A31: Hotels | B31: 8 | C31: 8 | D31: 9 | F31: 11 | H31: - | J31: - | K31: - | L31: - | M31: 36.663245 | N31: 37.491387 | O31: 42.621856 | P31: 38.453286 | Q31: 40.343423 | R31: 44.192331 | S31: 40.4 | T31: 45.412557 | U31: 17.074462 | V31: cawtWToh
A32: Guest Houses | B32: 17 | C32: 28 | D32: 21 | F32: 24 | H32: - | J32: - | K32: - | L32: - | M32: 18.438427 | N32: 23.215801 | O32: 18.290859 | P32: 23.754187 | Q32: 33.51556 | R32: 30.768032 | S32: 32.6 | T32: 33.867677 | U32: 18.371216 | V32: cawtegIluk
A33: Safari Vessels | B33: 96 | C33: 121 | D33: 116 | F33: 133 | H33: - | J33: - | K33: - | L33: - | M33: 41.030047 | N33: 46.93881 | O33: 26.948089 | P33: 29.175364 | Q33: 28.964643 | R33: 26.385018 | S33: 28.1 | T33: 26.15365 | U33: 12.572499 | V33: cawtudnwLua
A34: Note:1_/: 2018 data revised | V34: ނޯޓް: /_1: 2018 ގެ މަޢުލޫމާތު އިސްލާޙުކުރެވިފައި
A35: Source: Ministry of Tourism | V35: cmwzirUT cfoa IrcTcsinim :ctWrwf ivcaed utWmUluAwm
AE37: Resorts (including Marinas) | AF37: =T7/$T$6*100 -> 72.045481
AE38: Hotels | AF38: =T8/$T$6*100 -> 3.196916
AE39: Guest Houses | AF39: =T9/$T$6*100 -> 18.988747
AE40: Safari Vessels | AF40: =T10/$T$6*100 -> 5.7688564
AE44: Resorts (including Marinas) | AF44: =T19/$T$18 -> 0.17484009
AE45: Hotels | AF45: =T20/$T$18 -> 0.012793177
...

Sheet 10.3
A1: 2020 - 2019 ,urwvcnim unuverukcnunEb wgWjegudnea iaWa wgWj egudnea uhwmcswmikea : 10.3 ulwvWt
A2: Table 10.3: BED CAPACITY AND UTILIZATION BY MONTH, 2019 - 2020
A3: Month | B3: 2014 1_/ | H3: 2015 1_/ | N3: 20161_/ | T3: 2017 | Z3: 2018 | AG3: 2019 | AM3: 2020
B4: އެނދުގެ ޖާގަ | C4: ބޭނުންކުރެވުނު އެނދުގެ އަދަދު | D4: އެނދުގެ ޖާގައިން ބޭނުންކުރެވުނު މިންވަރު % | E4: އެނދުގެ ޖާގަ ބޭނުންކުރި މިންވަރު % | F4: ފަތުރުވެރިން ހޭދަކޮށްފައިވާ ރޭގެ އަދަދު | G4: ފަތުރުވެރިން އެވަރެޖްކޮށް ހޭދަކޮށްފައިވާ މުއްދަތު | H4: އެނދުގެ ޖާގަ | I4: ބޭނުންކުރެވުނު އެނދުގެ އަދަދު | J4: އެނދުގެ ޖާގައިން ބޭނުންކުރެވުނު މިންވަރު % | K4: އެނދުގެ ޖާގަ ބޭނުންކުރި މިންވަރު % | L4: ފަތުރުވެރިން ހޭދަކޮށްފައިވާ ރޭގެ އަދަދު | M4: ފަތުރުވެރިން އެވަރެޖްކޮށް ހޭދަކޮށްފައިވާ މުއްދަތު | N4: އެނދުގެ ޖާގަ | O4: ބޭނުންކުރެވުނު އެނދުގެ އަދަދު | P4: އެނދުގެ ޖާގައިން ބޭނުންކުރެވުނު މިންވަރު % | Q4: އެނދުގެ ޖާގަ ބޭނުންކުރި މިންވަރު % | R4: ފަތުރުވެރިން ހޭދަކޮށްފައިވާ ރޭގެ އަދަދު | S4: ފަތުރުވެރިން އެވަރެޖްކޮށް ހޭދަކޮށްފައިވާ މުއްދަތު | T4: އެނދުގެ ޖާގަ | U4: ބޭނުންކުރެވުނު އެނދުގެ އަދަދު | V4: އެނދުގެ ޖާގައިން ބޭނުންކުރެވުނު މިންވަރު % | W4: އެނދުގެ ޖާގަ ބޭނުންކުރި މިންވަރު % | X4: ފަތުރުވެރިން ހޭދަކޮށްފައިވާ ރޭގެ އަދަދު | Y4: ފަތުރުވެރިން އެވަރެޖްކޮށް ހޭދަކޮށްފައިވާ މުއްދަތު | Z4: އެނދުގެ ޖާގަ | AA4: ބޭނުންކުރެވުނު އެނދުގެ އަދަދު | AB4: އެނދުގެ ޖާގައިން ބޭނުންކުރެވުނު މިންވަރު % | AC4: އެނދުގެ ޖާގަ ބޭނުންކުރި މިންވަރު % | AD4: ފަތުރުވެރިން ހޭދަކޮށްފައިވާ ރޭގެ އަދަދު | AE4: ފަތުރުވެރިން އެވަރެޖްކޮށް ހޭދަކޮށްފައިވާ މުއްދަތު | AG4: އެނދުގެ ޖާގަ | AH4: ބޭނުންކުރެވުނު އެނދުގެ އަދަދު | AI4: އެނދުގެ ޖާގައިން ބޭނުންކުރެވުނު މިންވަރު % | AJ4: އެނދުގެ ޖާގަ ބޭނުންކުރި މިންވަރު % | AK4: ފަތުރުވެރިން ހޭދަކޮށްފައިވާ ރޭގެ އަދަދު | AL4: ފަތުރުވެރިން އެވަރެޖްކޮށް ހޭދަކޮށްފައިވާ މުއްދަތު | AM4: އެނދުގެ ޖާގަ | AN4: ބޭނުންކުރެވުނު އެނދުގެ އަދަދު | AO4: އެނދުގެ ޖާގައިން ބޭނުންކުރެވުނު މިންވަރު % | AP4: އެނދުގެ ޖާގަ ބޭނުންކުރި މިންވަރު % | AQ4: ފަތުރުވެރިން ހޭދަކޮށްފައިވާ ރޭގެ އަދަދު | AR4: ފަތުރުވެރިން އެވަރެޖްކޮށް ހޭދަކޮށްފައިވާ މުއްދަތު
B5: Registered Bed Capacity * | C5: Beds in operation | D5: % share of registered beds in operation | E5: Bed Capacity Utilization Rate % | F5: Tourist Bednights | G5: Average Duration of stay (days) | H5: Registered Bed Capacity | I5: Beds in operation | J5: % share of registered beds in operation | K5: Bed Capacity Utilization Rate % | L5: Tourist Bednights | M5: Average Duration of stay (days) | N5: Registered Bed Capacity | O5: Beds in operation | P5: % share of registered beds in operation | Q5: Bed Capacity Utilization Rate % | R5: Tourist Bednights | S5: Average Duration of stay (days) | T5: Registered Bed Capacity | U5: Beds in operation | V5: % share of registered beds in operation | W5: Bed Capacity Utilization Rate % | X5: Tourist Bednights | Y5: Average Duration of stay (days) | Z5: Registered Bed Capacity 1_/ | AA5: Beds in operation1_/ | AB5: % share of registered beds in operation | AC5: Bed Capacity Utilization Rate % | AD5: Tourist Bednights | AE5: Average Duration of stay (days) | AG5: Registered Bed Capacity | AH5: Beds in operation | AI5: % share of registered beds in operation | AJ5: Bed Capacity Utilization Rate % | AK5: Tourist Bednights | AL5: Average Duration of stay (days) | AM5: Registered Bed Capacity | AN5: Beds in operation | AO5: % share of registered beds in operation | AP5: Bed Capacity Utilization Rate % | AQ5: Tourist Bednights | AR5: Average Duration of stay (days)
A6: Annual Average | B6: =AVERAGE(B7:B18) -> 30586.667 | C6: =AVERAGE(C7:C18) -> 29515.25 | D6: =AVERAGE(D7:D18) -> 96.506881 | E6: =AVERAGE(E7:E18) -> 69.743726 | F6: =SUM(F7:F18) -> 7505622.3 | G6: =AVERAGE(G7:G18) -> 6.056923 | H6: =AVERAGE(H7:H18) -> 32835.25 | I6: =AVERAGE(I7:I18) -> 31423.917 | J6: =AVERAGE(J7:J18) -> 95.7103 | K6: =AVERAGE(K7:K18) -> 63.947493 | L6: =SUM(L7:L18) -> 7322683.1 | M6: =AVERAGE(M7:M18) -> 5.6623346 | N6: =AVERAGE(N7:N18) -> 35352.583 | O6: =AVERAGE(O7:O18) -> 33802.25 | P6: =AVERAGE(P7:P18) -> 95.601944 | Q6: =AVERAGE(Q7:Q18) -> 62.896552 | R6: =SUM(R7:R18) -> 7770922.6 | S6: =AVERAGE(S7:S18) -> 6.025 | T6: =AVERAGE(T7:T18) -> 39535.833 | U6: =AVERAGE(U7:U18) -> 38592.333 | V6: =AVERAGE(V7:V18) -> 97.601595 | W6: =AVERAGE(W7:W18) -> 61.105983 | X6: =SUM(X7:X18) -> 8593283.6 | Y6: =AVERAGE(Y7:Y18) -> 6.175 | Z6: =AVERAGE(Z7:Z18) -> 43050.083 | AA6: =AVERAGE(AA7:AA18) -> 41886.5 | AB6: =AVERAGE(AB7:AB18) -> 97.299233 | AC6: =AVERAGE(AC7:AC18) -> 62.132135 | AD6: =SUM(AD7:AD18) -> 9478093.9 | AE6: =AVERAGE(AE7:AE18) -> 6.3666667 | AG6: =AVERAGE(AG7:AG18) -> 48904.417 | AH6: =AVERAGE(AH7:AH18) -> 47268.5 | AI6: =AVERAGE(AI7:AI18) -> 96.656968 | AJ6: =AVERAGE(AJ7:AJ18) -> 62.27169 | AK6: =SUM(AK7:AK18) -> 10688387 | AL6: =AVERAGE(AL7:AL18) -> 6.2969106 | AM6: =AVERAGE(AM7:AM18) -> 52341.083 | AN6: =AVERAGE(AN7:AN18) -> 27744.667 | AO6: =AVERAGE(AO7:AO18) -> 53.023494 | AP6: =AVERAGE(AP7:AP18) -> 25.684781 | AQ6: =SUM(AQ7:AQ18) -> 3984712.4 | AR6: 7.1732772
A7: January | B7: 29815 | C7: 29074 | D7: =C7/B7*100 -> 97.514674 | E7: 77.894365 | F7: 702057.24 | G7: 6.4975118 | H7: 32031 | I7: 31029 | J7: =I7/H7*100 -> 96.87178 | K7: 68.982454 | L7: 663541.54 | M7: 6.4986144 | N7: 34012 | O7: 32548 | P7: =O7/N7*100 -> 95.695637 | Q7: 65.312077 | R7: 658991.02 | S7: 6.1 | T7: 37575 | U7: 36225 | V7: 96.407186 | W7: 71.250594 | X7: 800126.36 | Y7: 6.4 | Z7: 41602 | AA7: 40943 | AB7: 98.415942 | AC7: 74.178416 | AD7: 941496.94 | AE7: 6.6 | AG7: 45565 | AH7: 44266 | AI7: 97.149128 | AJ7: 72.760799 | AK7: 998457.16 | AL7: 6.588215 | AM7: 52016 | AN7: 50679 | AO7: 97.429637 | AP7: 72.736012 | AQ7: 1142718.4 | AR7: 6.5920863
A8: February | B8: 29885 | C8: 29183 | D8: =C8/B8*100 -> 97.650995 | E8: 85.89086 | F8: 701834.83 | G8: 6.1376541 | H8: 32122 | I8: 31068 | J8: =I8/H8*100 -> 96.71876 | K8: 82.039189 | L8: 713662.18 | M8: 5.6647325 | N8: 34152 | O8: 32741 | P8: =O8/N8*100 -> 95.86847 | Q8: 78.932965 | R8: 749459.82 | S8: 6.2 | T8: 38146 | U8: 37133 | V8: 97.344414 | W8: 74.290195 | X8: 772412.99 | Y8: 6.4 | Z8: 41710 | AA8: 40807 | AB8: 97.835052 | AC8: 81.007215 | AD8: 925585.2 | AE8: 6.4 | AG8: 46073 | AH8: 44680 | AI8: 96.976537 | AJ8: 81.503171 | AK8: 1019637.3 | AL8: 6.0482805 | AM8: 52263 | AN8: 50926 | AO8: 97.441785 | AP8: 69.086698 | AQ8: 1020309.7 | AR8: 6.8118281
A9: March | B9: 30271 | C9: 29445 | D9: =C9/B9*100 -> 97.271316 | E9: 77.392769 | F9: 706437.32 | G9: 6.4923551 | H9: 32345 | I9: 31307 | J9: =I9/H9*100 -> 96.790849 | K9: 71.391083 | L9: 692862.6 | M9: 5.837121 | N9: 34364 | O9: 32874 | P9: =O9/N9*100 -> 95.664067 | Q9: 73.258061 | R9: 746568.5 | S9: 6.5 | T9: 38719 | U9: 37773 | V9: 97.556755 | W9: 64.086718 | X9: 750431.76 | Y9: 6.7 | Z9: 42050 | AA9: 41137 | AB9: 97.828775 | AC9: 68.514513 | AD9: 873729.27 | AE9: 6.5 | AG9: 47107 | AH9: 45216 | AI9: 95.985735 | AJ9: 71.825154 | AK9: 1006770.3 | AL9: 6.1824598 | AM9: 52319 | AN9: 51001 | AO9: 97.480839 | AP9: 35.56554 | AQ9: 562302.21 | AR9: 9.4298542
A10: April | B10: 30368 | C10: 29540 | D10: =C10/B10*100 -> 97.273446 | E10: 75.977205 | F10: 673309.99 | G10: 6.1507943 | H10: 32443 | I10: 31212 | J10: =I10/H10*100 -> 96.205653 | K10: 68.405485 | L10: 640521.6 | M10: 5.8961777 | N10: 34548 | O10: 33188 | P10: =O10/N10*100 -> 96.063448 | Q10: 65.879424 | R10: 655921.9 | S10: 6.3 | T10: 39070 | U10: 37817 | V10: 96.792936 | W10: 65.446547 | X10: 742497.62 | Y10: 6.2 | Z10: 42688 | AA10: 41835 | AB10: 98.00178 | AC10: 63.490693 | AD10: 796839.94 | AE10: 6.7 | AG10: 47351 | AH10: 45936 | AI10: 97.011679 | AJ10: 71.241824 | AK10: 981769.33 | AL10: 6.0189152 | AM10: 52319 | AN10: 7690 | AO10: 14.698293 | AP10: 3.8335588 | AQ10: 8844.0203 | AR10: 9.428593
A11: May | B11: 30348 | C11: 29266 | D11: =C11/B11*100 -> 96.434691 | E11: 63.656332 | F11: 577519.53 | G11: 6.1992749 | H11: 32614 | I11: 31301 | J11: =I11/H11*100 -> 95.974122 | K11: 59.290817 | L11: 575317.18 | M11: 5.8370252 | N11: 34912 | O11: 33284 | P11: =O11/N11*100 -> 95.336847 | Q11: 55.5789 | R11: 573465.31 | S11: 6.2 | T11: 39505 | U11: 38264 | V11: 96.858625 | W11: 50.708521 | X11: 601496.37 | Y11: 6.4 | Z11: 42736 | AA11: 41513 | AB11: 97.138244 | AC11: 49.851767 | AD11: 641543.89 | AE11: 6.9 | AG11: 48603 | AH11: 47196 | AI11: 97.105117 | AJ11: 49.074134 | AK11: 717991.88 | AL11: 6.9693064 | AM11: 52319 | AN11: 2978 | AO11: 5.6920048 | AP11: 5.1740951 | AQ11: 4776.6212 | AR11: 86.847657
A12: June | B12: 30488 | C12: 28938 | D12: =C12/B12*100 -> 94.916033 | E12: 54.447089 | F12: 472676.96 | G12: 5.5955943 | H12: 32694 | I12: 31089 | J12: =I12/H12*100 -> 95.090842 | K12: 48.021539 | L12: 447882.49 | M12: 5.3335092 | N12: 35086 | O12: 33160 | P12: =O12/N12*100 -> 94.510631 | Q12: 44.625767 | R12: 443937.13 | S12: 5.6 | T12: 39570 | U12: 38648 | V12: 97.669952 | W12: 41.476026 | X12: 480889.64 | Y12: 5.6 | Z12: 42822 | AA12: 41503 | AB12: 96.919808 | AC12: 43.735771 | AD12: 544549.71 | AE12: 5.8 | AG12: 48873 | AH12: 47477 | AI12: 97.143617 | AJ12: 50.172152 | AK12: 714606.98 | AL12: 6.2974839 | AM12: 52287 | AN12: 3078 | AO12: 5.8867405 | AP12: 2.5187364 | AQ12: 2325.8012 | AR12: 42.287294
A13: July | B13: 30658 | C13: 29684 | D13: =C13/B13*100 -> 96.823015 | E13: 62.667044 | F13: 576664.65 | G13: 5.7481211 | H13: 32740 | I13: 31138 | J13: =I13/H13*100 -> 95.106903 | K13: 59.092551 | L13: 570407.4 | M13: 5.2416292 | N13: 35517 | O13: 33581 | P13: =O13/N13*100 -> 94.549089 | Q13: 60.453462 | R13: 629327.19 | S13: 5.7 | T13: 39799 | U13: 38979 | V13: 97.939647 | W13: 56.938909 | X13: 688020.73 | Y13: 6.1 | Z13: 42929 | AA13: 41534 | AB13: 96.750448 | AC13: 57.746224 | AD13: 743513.82 | AE13: 6.1 | AG13: 49189 | AH13: 47174 | AI13: 95.903556 | AJ13: 53.112087 | AK13: 776707.97 | AL13: 5.8777392 | AM13: 52236 | AN13: 9821 | AO13: 18.80121 | AP13: 8.1042351 | AQ13: 24673.425 | AR13: 14.083005
A14: August | B14: 30696 | C14: 29652 | D14: =C14/B14*100 -> 96.598905 | E14: 70.103727 | F14: 644401.87 | G14: 6.0467913 | H14: 32902 | I14: 31274 | J14: =I14/H14*100 -> 95.051973 | K14: 65.484146 | L14: 634864.87 | M14: 5.5166509 | N14: 35681 | O14: 33745 | P14: =O14/N14*100 -> 94.574143 | Q14: 64.919557 | R14: 679120.24 | S14: 6 | T14: 39937 | U14: 39074 | V14: 97.839097 | W14: 61.63806 | X14: 746618.12 | Y14: 6.2 | Z14: 43099 | AA14: 41780 | AB14: 96.939604 | AC14: 63.537355 | AD14: 822923.11 | AE14: 6.6 | AG14: 49740 | AH14: 47102 | AI14: 94.696421 | AJ14: 62.365862 | AK14: 910642.62 | AL14: 6.5354937 | AM14: 52361 | AN14: 19263 | AO14: 36.788831 | AP14: 11.951827 | AQ14: 71370.695 | AR14: 9.3485538
A15: September | B15: 30803 | C15: 29703 | D15: =C15/B15*100 -> 96.428919 | E15: 61.818035 | F15: 550854.33 | G15: 5.6810669 | H15: 33041 | I15: 31477 | J15: =I15/H15*100 -> 95.266487 | K15: 57.723156 | L15: 545085.54 | M15: 5.4870643 | N15: 35809 | O15: 33967 | P15: =O15/N15*100 -> 94.856042 | Q15: 57.880754 | R15: 589810.67 | S15: 5.8 | T15: 39991 | U15: 39262 | V15: 98.17709 | W15: 51.294326 | X15: 604175.35 | Y15: 5.7 | Z15: 43660 | AA15: 42355 | AB15: 97.010994 | AC15: 51.029853 | AD15: 648410.82 | AE15: 6 | AG15: 50802 | AH15: 49213 | AI15: 96.87217 | AJ15: 48.011841 | AK15: 708842.02 | AL15: 6.0265945 | AM15: 52311 | AN15: 25328 | AO15: 48.418115 | AP15: 9.9189122 | AQ15: 75367.862 | AR15: 9.4824196 | CB15: Registered Bed Capacity | CC15: Beds in operation
A16: October | B16: 30812 | C16: 29625 | D16: =C16/B16*100 -> 96.147605 | E16: 74.500473 | F16: 684193.72 | G16: 6.0237286 | H16: 33415 | I16: 31406 | J16: =I16/H16*100 -> 93.98773 | K16: 65.599745 | L16: 638669.93 | M16: 5.7831712 | N16: 36062 | O16: 34114 | P16: =O16/N16*100 -> 94.598192 | Q16: 66.797619 | R16: 706407.53 | S16: 6 | T16: 40169 | U16: 39545 | V16: 98.446563 | W16: 64.726132 | X16: 793474.42 | Y16: 6.2 | Z16: 43806 | AA16: 42501 | AB16: 97.020956 | AC16: 62.289752 | AD16: 820686.79 | AE16: 6.4 | AG16: 51039 | AH16: 49450 | AI16: 96.886694 | AJ16: 59.780902 | AK16: 916411.33 | AL16: 6.4568749 | AM16: 52867 | AN16: 32600 | AO16: 61.664176 | AP16: 16.792903 | AQ16: 169709.08 | AR16: 9.615996 | CA16: Jan | CB16: =AM7 -> 52016 | CC16: =AN7 -> 50679
A17: November | B17: 31223 | C17: 29815 | D17: =C17/B17*100 -> 95.490504 | E17: 64.058213 | F17: 572968.69 | G17: 6.156085 | H17: 33591 | I17: 32138 | J17: =I17/H17*100 -> 95.674437 | K17: 58.808084 | L17: 566992.27 | M17: 5.9014498 | N17: 36714 | O17: 35807 | P17: =O17/N17*100 -> 97.529553 | Q17: 60.691939 | R17: 651958.88 | S17: 6.2 | T17: 40694 | U17: 39816 | V17: 97.842434 | W17: 62.79321 | X17: 750052.33 | Y17: 6.2 | Z17: 44345 | AA17: 42960 | AB17: 96.876762 | AC17: 62.784267 | AD17: 809163.63 | AE17: 6.4 | AG17: 51149 | AH17: 49658 | AI17: 97.084987 | AJ17: 59.543682 | AK17: 887046.05 | AL17: 6.4315518 | AM17: 52968 | AN17: 37378 | AO17: 70.567135 | AP17: 24.883647 | AQ17: 279030.28 | AR17: 8.8770985 | CA17: Feb | CB17: =AM8 -> 52263 | CC17: =AN8 -> 50926
A18: December | B18: 31673 | C18: 30258 | D18: =C18/B18*100 -> 95.532472 | E18: 68.518604 | F18: 642703.14 | G18: 5.9540986 | H18: 34085 | I18: 32648 | J18: =I18/H18*100 -> 95.784069 | K18: 62.531665 | L18: 632875.48 | M18: 4.95087 | N18: 37374 | O18: 36618 | P18: =O18/N18*100 -> 97.977203 | Q18: 60.428102 | R18: 685954.43 | S18: 5.7 | T18: 41255 | U18: 40572 | V18: 98.344443 | W18: 68.622562 | X18: 863087.93 | Y18: 6 | Z18: 45154 | AA18: 43770 | AB18: 96.85243 | AC18: 67.419799 | AD18: 909650.78 | AE18: 6 | AG18: 51362 | AH18: 49854 | AI18: 97.067973 | AJ18: 67.868666 | AK18: 1049504.2 | AL18: 6.1300122 | AM18: 51827 | AN18: 42194 | AO18: 81.413163 | AP18: 47.651202 | AQ18: 623284.4 | AR18: 9.1055877 | CA18: Mar | CB18: =AM9 -> 52319 | CC18: =AN9 -> 51001
A19: Note: Maldives border was closed for international visitirs on 27th March 2020 due to global COVID-19 outbreak and was re-opened on 15th July 2020 | AR19: cmwzirUT cfoa IrcTcsinim :ctWrwf ivcaed utWmUluAwm | CA19: Apr | CB19: =AM10 -> 52319 | CC19: =AN10 -> 7690
A20: May, June and July 2020, Average Duration of Stay is based on estimated number of tourists in the Maldives. | CA20: May | CB20: =AM11 -> 52319 | CC20: =AN11 -> 2978
A21: Due to COVIC-19 pandamic, some tourists were unable to travel back to their home country. | CA21: Jun | CB21: =AM12 -> 52287 | CC21: =AN12 -> 3078
A22: Source: Ministry of Tourism | CA22: Jul | CB22: =AM13 -> 52236 | CC22: =AN13 -> 9821
CA23: Aug | CB23: =AM14 -> 52361 | CC23: =AN14 -> 19263
CA24: Sep | CB24: =AM15 -> 52311 | CC24: =AN15 -> 25328
BN25: 41640 | BO25: =G7 -> 6.4975118 | CA25: Oct | CB25: =AM16 -> 52867 | CC25: =AN16 -> 32600
BN26: February | BO26: =G8 -> 6.1376541 | CA26: Nov | CB26: =AM17 -> 52968 | CC26: =AN17 -> 37378
BN27: March | BO27: =G9 -> 6.4923551 | CA27: Dec | CB27: =AM18 -> 51827 | CC27: =AN18 -> 42194
BN28: April | BO28: =G10 -> 6.1507943
BN29: May | BO29: =G11 -> 6.1992749
BN30: June | BO30: =G12 -> 5.5955943
BN31: July | BO31: =G13 -> 5.7481211
BN32: August | BO32: =G14 -> 6.0467913
BN33: September | BO33: =G15 -> 5.6810669
BN34: October | BO34: =G16 -> 6.0237286
BN35: November | BO35: =G17 -> 6.156085
BN36: December | BO36: =G18 -> 5.9540986
BN37: 42005 | BO37: 6.4986144
BN38: February | BO38: 5.6647325
BN39: March | BO39: 5.837121
BN40: April | BO40: 5.8961777
...

Sheet 10.4
A1: 2020 - 2019 ,urwvcnim unuverukcnunEb wgWjegudnea iaWa wgWj egudnea egukwtuTOsir uhwmcswmikea : 10.4 ulwvWt
A2: Table 10.4: BED CAPACITY AND UTILIZATION OF RESORTS BY MONTH, 2019 - 2020
A4: Month | B4: 2014 | G4: 2015 | L4: 2016 | Q4: 2017 | V4: 2018 | AA4: 2019 | AF4: 2020
B5: އެނދުގެ ޖާގަ | C5: ބޭނުންކުރެވުނު އެނދުގެ އަދަދު | D5: އެނދުގެ ޖާގައިން ބޭނުންކުރެވުނު މިންވަރު % | E5: އެނދުގެ ޖާގަ ބޭނުންކުރި މިންވަރު % | F5: ފަތުރުވެރިން ހޭދަކޮށްފައިވާ ރޭގެ އަދަދު | G5: އެނދުގެ ޖާގަ | H5: ބޭނުންކުރެވުނު އެނދުގެ އަދަދު | I5: އެނދުގެ ޖާގައިން ބޭނުންކުރެވުނު މިންވަރު % | J5: އެނދުގެ ޖާގަ ބޭނުންކުރި މިންވަރު % | K5: ފަތުރުވެރިން ހޭދަކޮށްފައިވާ ރޭގެ އަދަދު | L5: އެނދުގެ ޖާގަ | M5: ބޭނުންކުރެވުނު އެނދުގެ އަދަދު | N5: އެނދުގެ ޖާގައިން ބޭނުންކުރެވުނު މިންވަރު % | O5: އެނދުގެ ޖާގަ ބޭނުންކުރި މިންވަރު % | P5: ފަތުރުވެރިން ހޭދަކޮށްފައިވާ ރޭގެ އަދަދު | Q5: އެނދުގެ ޖާގަ | R5: ބޭނުންކުރެވުނު އެނދުގެ އަދަދު | S5: އެނދުގެ ޖާގައިން ބޭނުންކުރެވުނު މިންވަރު % | T5: އެނދުގެ ޖާގަ ބޭނުންކުރި މިންވަރު % | U5: ފަތުރުވެރިން ހޭދަކޮށްފައިވާ ރޭގެ އަދަދު | V5: އެނދުގެ ޖާގަ | W5: ބޭނުންކުރެވުނު އެނދުގެ އަދަދު | X5: އެނދުގެ ޖާގައިން ބޭނުންކުރެވުނު މިންވަރު % | Y5: އެނދުގެ ޖާގަ ބޭނުންކުރި މިންވަރު % | Z5: ފަތުރުވެރިން ހޭދަކޮށްފައިވާ ރޭގެ އަދަދު | AA5: އެނދުގެ ޖާގަ | AB5: ބޭނުންކުރެވުނު އެނދުގެ އަދަދު | AC5: އެނދުގެ ޖާގައިން ބޭނުންކުރެވުނު މިންވަރު % | AD5: އެނދުގެ ޖާގަ ބޭނުންކުރި މިންވަރު % | AE5: ފަތުރުވެރިން ހޭދަކޮށްފައިވާ ރޭގެ އަދަދު | AF5: އެނދުގެ ޖާގަ | AG5: ބޭނުންކުރެވުނު އެނދުގެ އަދަދު | AH5: އެނދުގެ ޖާގައިން ބޭނުންކުރެވުނު މިންވަރު % | AI5: އެނދުގެ ޖާގަ ބޭނުންކުރި މިންވަރު % | AJ5: ފަތުރުވެރިން ހޭދަކޮށްފައިވާ ރޭގެ އަދަދު
B6: Registered Bed Capacity | C6: Beds in operation | D6: % share of registered beds in operation | E6: Bed Capacity Utilization Rate % | F6: Tourist Bednights | G6: Registered Bed Capacity | H6: Beds in operation | I6: % share of registered beds in operation | J6: Bed Capacity Utilization Rate % | K6: Tourist Bednights | L6: Registered Bed Capacity | M6: Beds in operation | N6: % share of registered beds in operation | O6: Bed Capacity Utilization Rate % | P6: Tourist Bednights | Q6: Registered Bed Capacity | R6: Beds in operation | S6: % share of registered beds in operation | T6: Bed Capacity Utilization Rate % | U6: Tourist Bednights | V6: Registered Bed Capacity 1_/ | W6: Beds in operation1_/ | X6: % share of registered beds in operation | Y6: Bed Capacity Utilization Rate % | Z6: Tourist Bednights | AA6: Registered Bed Capacity | AB6: Beds in operation | AC6: % share of registered beds in operation | AD6: Bed Capacity Utilization Rate % | AE6: Tourist Bednights | AF6: Registered Bed Capacity | AG6: Beds in operation | AH6: % share of registered beds in operation | AI6: Bed Capacity Utilization Rate % | AJ6: Tourist Bednights
A7: Annual Average | B7: =AVERAGE(B8:B19) -> 23749 | C7: =AVERAGE(C8:C19) -> 22986.167 | D7: =AVERAGE(D8:D19) -> 96.791549 | E7: =AVERAGE(E8:E19) -> 81.856214 | F7: =SUM(F8:F19) -> 6864861 | G7: =AVERAGE(G8:G19) -> 24277.167 | H7: =AVERAGE(H8:H19) -> 23348.417 | I7: =AVERAGE(I8:I19) -> 96.178937 | J7: =AVERAGE(J8:J19) -> 76.220607 | K7: =SUM(K8:K19) -> 6489783.4 | L7: =AVERAGE(L8:L19) -> 25685.333 | M7: =AVERAGE(M8:M19) -> 24567.667 | N7: =AVERAGE(N8:N19) -> 95.634598 | O7: =AVERAGE(O8:O19) -> 73.996437 | P7: =SUM(P8:P19) -> 6645765 | Q7: =AVERAGE(Q8:Q19) -> 28447.333 | R7: =AVERAGE(R8:R19) -> 27685.917 | S7: =AVERAGE(S8:S19) -> 97.31832 | T7: =AVERAGE(T8:T19) -> 72.738666 | U7: =SUM(U8:U19) -> 7343577.1 | V7: =AVERAGE(V8:V19) -> 30544.833 | W7: =AVERAGE(W8:W19) -> 29399.667 | X7: =AVERAGE(X8:X19) -> 96.256585 | Y7: =AVERAGE(Y8:Y19) -> 74.635417 | Z7: =SUM(Z8:Z19) -> 8000462.8 | AA7: =AVERAGE(AA8:AA19) -> 35016.083 | AB7: =AVERAGE(AB8:AB19) -> 33439.75 | AC7: =AVERAGE(AC8:AC19) -> 95.496713 | AD7: =AVERAGE(AD8:AD19) -> 74.139743 | AE7: =SUM(AE8:AE19) -> 8997786.6 | AF7: =AVERAGE(AF8:AF19) -> 37566.333 | AG7: =AVERAGE(AG8:AG19) -> 21445.667 | AH7: =AVERAGE(AH8:AH19) -> 57.094233 | AI7: =AVERAGE(AI8:AI19) -> 28.978641 | AJ7: =SUM(AJ8:AJ19) -> 3357345.2
A8: January | B8: 23487 | C8: 22987 | D8: =C8/B8*100 -> 97.871163 | E8: 90.256765 | F8: 643167 | G8: 24047 | H8: 23447 | I8: =H8/G8*100 -> 97.504886 | J8: 80.14809 | K8: 582562 | L8: 25047 | M8: 23986 | N8: =M8/L8*100 -> 95.763964 | O8: 75.39788 | P8: 560633 | Q8: 27083 | R8: 26302 | S8: =R8/Q8*100 -> 97.116272 | T8: 83.731194 | U8: 682712.34 | V8: 30063 | W8: 29404 | X8: =W8/V8*100 -> 97.807937 | Y8: 86.115794 | Z8: 784966.13 | AA8: 32213 | AB8: 30938 | AC8: 96.041971 | AD8: 84.878364 | AE8: 814049.72 | AF8: 37394 | AG8: 36094 | AH8: 96.523506 | AI8: 83.21671 | AJ8: 931123.42
A9: February | B9: 23487 | C9: 22987 | D9: =C9/B9*100 -> 97.871163 | E9: 98.0099 | F9: 630827 | G9: 24107 | H9: 23507 | I9: =H9/G9*100 -> 97.511096 | J9: 95.221788 | K9: 626746 | L9: 25079 | M9: 24076 | N9: =M9/L9*100 -> 96.000638 | O9: 91.065792 | P9: 635825 | Q9: 27497 | R9: 26726 | S9: =R9/Q9*100 -> 97.196058 | T9: 86.162898 | U9: 644781.09 | V9: 30063 | W9: 29160 | X9: =W9/V9*100 -> 96.996308 | Y9: 94.025822 | Z9: 767702.03 | AA9: 32437 | AB9: 31068 | AC9: 95.779511 | AD9: 94.565353 | AE9: 822627.79 | AF9: 37522 | AG9: 36222 | AH9: 96.535366 | AI9: 79.284758 | AJ9: 832837.22
A10: March | B10: 23715 | C10: 23023 | D10: =C10/B10*100 -> 97.082016 | E10: 87.894013 | F10: 627311 | G10: 24123 | H10: 23527 | I10: =H10/G10*100 -> 97.529329 | J10: 82.752418 | K10: 603544 | L10: 25079 | M10: 24086 | N10: =M10/L10*100 -> 96.040512 | O10: 84.819853 | P10: 633321 | Q10: 27973 | R10: 27202 | S10: =R10/Q10*100 -> 97.243771 | T10: 73.328085 | U10: 618347.88 | V10: 30181 | W10: 29268 | X10: =W10/V10*100 -> 96.974918 | Y10: 80.002029 | Z10: 725864.81 | AA10: 33355 | AB10: 31488 | AC10: 94.402638 | AD10: 83.700141 | AE10: 817020.51 | AF10: 37522 | AG10: 36222 | AH10: 96.535366 | AI10: 41.804754 | AJ10: 469418.05
A11: April | B11: 23715 | C11: 23243 | D11: =C11/B11*100 -> 98.009699 | E11: 87.080698 | F11: 607205 | G11: 24123 | H11: 23415 | I11: =H11/G11*100 -> 97.065042 | J11: 79.978361 | K11: 561808 | L11: 25153 | M11: 24182 | N11: =M11/L11*100 -> 96.139625 | O11: 76.867091 | P11: 557640 | Q11: 28291 | R11: 27202 | S11: =R11/Q11*100 -> 96.150719 | T11: 77.118214 | U11: 629330.9 | V11: 30187 | W11: 29334 | X11: =W11/V11*100 -> 97.17428 | Y11: 76.225942 | Z11: 670803.54 | AA11: 33509 | AB11: 32118 | AC11: 95.848876 | AD11: 84.445085 | AE11: 813662.17 | AF11: 37522 | AG11: 7064 | AH11: 18.826289 | AI11: 3.8354191 | AJ11: 8128.0203
A12: May | B12: 23715 | C12: 22905 | D12: =C12/B12*100 -> 96.58444 | E12: 75.539219 | F12: 536370 | G12: 24123 | H12: 23321 | I12: =H12/G12*100 -> 96.675372 | J12: 72.083724 | K12: 521130 | L12: 25425 | M12: 24182 | N12: =M12/L12*100 -> 95.111111 | O12: 67.042402 | P12: 502578 | Q12: 28549 | R12: 27472 | S12: =R12/Q12*100 -> 96.227539 | T12: 61.332135 | U12: 522324.09 | V12: 30187 | W12: 28964 | X12: =W12/V12*100 -> 95.948587 | Y12: 61.569198 | Z12: 552819.98 | AA12: 34735 | AB12: 33352 | AC12: 96.018425 | AD12: 59.108571 | AE12: 611130.61 | AF12: 37522 | AG12: 2904 | AH12: 7.7394595 | AI12: 5.1859739 | AJ12: 4668.6212
